<?xml version="1.0" ?>
<!-- =================================================================================== -->
<!-- |    This document was autogenerated by xacro from linemod_template.xacro         | -->
<!-- |    EDITING THIS FILE BY HAND IS NOT RECOMMENDED                                 | -->
<!-- =================================================================================== -->
<!-- Revolute-Revolute Manipulator -->
<robot name="linemod_template" xmlns:xacro="http://www.ros.org/wiki/xacro">
  <!-- Space btw top of beam and the each joint -->
  <!-- ros_control plugin -->
  <gazebo>
    <plugin filename="libgazebo_ros_control.so" name="gazebo_ros_control">
      <robotNamespace>/linemod_template</robotNamespace>
      <robotSimType>gazebo_ros_control/DefaultRobotHWSim</robotSimType>
    </plugin>
  </gazebo>
  <gazebo reference="mesh_model_link">
  </gazebo>
  <!-- <xacro:include filename="$(find abe_kinect_description)/urdf/abe_kinect.xacro" /> -->
  <!-- Used for fixing robot to Gazebo 'base_link' -->
  <link name="world"/>
  <!-- <link name="camera_depth_frame"/> -->
  <!-- object -->
  <joint name="mesh_model_joint" type="floating">
    <axis xyz="0 0 0"/>
    <!-- for object1 -->
    <!-- <origin xyz="-0.06 -0.075 -0.08" rpy="0 0 0"/> -->
    <origin xyz="0.0 0.0 0.0" rpy="0 0 0"/>

    <parent link="world"/>
    <!-- <parent link="camera_depth_frame"/> -->
    <child link="mesh_model_link"/>
  </joint>
  <link name="mesh_model_link">
    <collision>
      <origin rpy="0 0 0" xyz="0.1 0.1 0"/>
      <geometry>
        <box size="0.1 0.1 0.1"/>
      </geometry>
    </collision>
    <visual>
      <geometry>

       <mesh filename="package://description_of_linemodtemp/meshes/taskboard_parts/dae/Bearing.dae"/>
       <!-- <mesh filename="package://description_of_linemodtemp/meshes/taskboard_parts/dae/Pin.dae"/> -->
       <!-- <mesh filename="package://description_of_linemodtemp/meshes/taskboard_parts/dae/Pin_.dae"/> -->
       <!-- <mesh filename="package://description_of_linemodtemp/meshes/taskboard_parts/dae/Spacer17_50.dae"/> -->
       <!-- <mesh filename="package://description_of_linemodtemp/meshes/taskboard_parts/dae/Spacer9_50.dae"/> -->
       <!-- <mesh filename="package://description_of_linemodtemp/meshes/taskboard_parts/dae/Spacer9_50_.dae"/> -->
       <!-- <mesh filename="package://description_of_linemodtemp/meshes/taskboard_parts/dae/Drive_Shaft.dae"/> -->
       <!-- <mesh filename="package://description_of_linemodtemp/meshes/taskboard_parts/dae/Drive_Shaft_.dae"/> -->
       <!-- <mesh filename="package://description_of_linemodtemp/meshes/taskboard_parts/dae/Belt.dae"/> -->
       <!-- <mesh filename="package://description_of_linemodtemp/meshes/taskboard_parts/dae/M6_Bolt.dae"/> -->
       <!-- <mesh filename="package://description_of_linemodtemp/meshes/taskboard_parts/dae/M6_Bolt_.dae"/> -->
       <!-- <mesh filename="package://description_of_linemodtemp/meshes/taskboard_parts/dae/M6_Nut.dae"/> -->
       <!-- <mesh filename="package://description_of_linemodtemp/meshes/taskboard_parts/dae/M6_Nut.dae_"/> -->
       <!-- <mesh filename="package://description_of_linemodtemp/meshes/taskboard_parts/dae/M12_Nut.dae"/> -->
       <!-- <mesh filename="package://description_of_linemodtemp/meshes/taskboard_parts/dae/M12_Nut_.dae"/> -->
       <!-- <mesh filename"package://description_of_linemodtemp/meshes/taskboard_parts/dae/6mm_Washer.dae"/> -->
       <!-- <mesh filename="package://description_of_linemodtemp/meshes/taskboard_parts/dae/6mm_Washer_.dae"/> -->
       <!-- <mesh filename="package://description_of_linemodtemp/meshes/taskboard_parts/dae/10mm_Washer.dae"/> -->
       <!-- <mesh filename="package://description_of_linemodtemp/meshes/taskboard_parts/dae/10mm_Washer_.dae"/> -->
       <!-- <mesh filename="package://description_of_linemodtemp/meshes/taskboard_parts/dae/M3_6.dae"/> -->
       <!-- <mesh filename="package://description_of_linemodtemp/meshes/taskboard_parts/dae/M4_6.dae"/> -->
       <!-- <mesh filename="package://description_of_linemodtemp/meshes/taskboard_parts/dae/Motor_Pulley.dae"/> -->
       <!-- <mesh filename="package://description_of_linemodtemp/meshes/taskboard_parts/dae/End_Cap.dae"/> -->
       <!-- <mesh filename="package://description_of_linemodtemp/meshes/taskboard_parts/dae/End_Cap_.dae"/> -->

       <!-- <mesh filename="package://description_of_linemodtemp/meshes/taskboard_parts/dae/TB_Plate.dae"/> -->
       <!-- <mesh filename="package://description_of_linemodtemp/meshes/taskboard_parts/dae/Mat.dae"/> -->

       
       
      </geometry>
    </visual>
    <inertial>
      <mass value="1e-5"/>
      <origin rpy="0 0 0" xyz="0.1 0.1 0"/>
      <inertia ixx="1e-6" ixy="0" ixz="0" iyy="1e-6" iyz="0" izz="1e-6"/>
    </inertial>
  </link>
</robot>
